<?xml version="1.0"?>

<robot
  name="timda_body"
  xmlns:xacro="http://www.ros.org/wiki/xacro">
  <link
    name="base_link">
    <inertial>
      <origin
        xyz="-0.12772 4.4082E-06 0.38955"
        rpy="0 0 0" />
      <mass
        value="29.072" />
      <inertia
        ixx="2.7119"
        ixy="7.603E-06"
        ixz="0.51848"
        iyy="3.3365"
        iyz="-4.3354E-05"
        izz="1.6033" />
    </inertial>
    <visual>
      <origin
        xyz="0 0 0"
        rpy="0 0 0" />
      <geometry>
        <mesh
          filename="package://timda_body/meshes/base_link.STL" />
      </geometry>
      <material
        name="">
        <color
          rgba="0.79216 0.81961 0.93333 1" />
      </material>
    </visual>
    <collision>
      <origin
        xyz="0 0 0"
        rpy="0 0 0" />
      <geometry>
        <mesh
          filename="package://timda_body/meshes/base_link.STL" />
      </geometry>
    </collision>
  </link>
  <link
    name="slide_right">
    <inertial>
      <origin
        xyz="1.5718E-05 -0.006626 2.4586E-06"
        rpy="0 0 0" />
      <mass
        value="0.24709" />
      <inertia
        ixx="0"
        ixy="0"
        ixz="0"
        iyy="0"
        iyz="0"
        izz="0" />
    </inertial>
    <visual>
      <origin
        xyz="0 0 0"
        rpy="0 0 0" />
      <geometry>
        <mesh
          filename="package://timda_body/meshes/slide_right.STL" />
      </geometry>
      <material
        name="">
        <color
          rgba="0.89804 0.91765 0.92941 1" />
      </material>
    </visual>
    <collision>
      <origin
        xyz="0 0 0"
        rpy="0 0 0" />
      <geometry>
        <mesh
          filename="package://timda_body/meshes/slide_right.STL" />
      </geometry>
    </collision>
  </link>
  <joint
    name="joint_right"
    type="prismatic">
    <origin
      xyz="-0.2 0.0765 1.1815"
      rpy="0 0 0" />
      <!--rpy="-2.0485E-16 -4.5768E-16 9.3918E-09" /-->
    <parent
      link="base_link" />
    <child
      link="slide_right" />
    <axis
      xyz="0 0 1" />
    <limit
      effort="0"
      velocity="0" />
  </joint>
  <link
    name="slide_left">
    <inertial>
      <origin
        xyz="-1.5722E-05 0.006626 2.4586E-06"
        rpy="0 0 0" />
      <mass
        value="0.24709" />
      <inertia
        ixx="0"
        ixy="0"
        ixz="0"
        iyy="0"
        iyz="0"
        izz="0" />
    </inertial>
    <visual>
      <origin
        xyz="0 0 0"
        rpy="0 0 0" />
      <geometry>
        <mesh
          filename="package://timda_body/meshes/slide_right.STL" />
      </geometry>
      <material
        name="">
        <color
          rgba="0.89804 0.91765 0.92941 1" />
      </material>
    </visual>
    <collision>
      <origin
        xyz="0 0 0"
        rpy="0 0 0" />
      <geometry>
        <mesh
          filename="package://timda_body/meshes/slide_right.STL" />
      </geometry>
    </collision>
  </link>
  <joint
    name="joint_left"
    type="prismatic">
    <origin
      xyz="-0.2 -0.0765 1.1815"
      rpy="0 0 3.1415926" />
	  <!--rpy="-2.0485E-16 -2.9114E-16 3.1415926" /-->
    <parent
      link="base_link" />
    <child
      link="slide_left" />
    <axis
      xyz="0 0 1" />
    <limit
      effort="0"
      velocity="0" />
  </joint>
</robot>
